Workbook

Sheet Catalogos
A1: Periodos | B1: Cursos | D1: titpo de sangre | E1: NUCLEO ESTRUCTURANTE | F1: OBJETIVOS
A3: ABRIL 2023 - AGOSTO 2023 | B3: PRIMERO | C3: 1ro | D3: A+ | E3: FUNDAMENTOS DE PROGRAMACIÓN | F3: Aplicar de forma autónoma la lógica de programación para el desarrollo de algoritmos sencillos utilizando una sintaxis adecuada.
A4: OCTUBRE 2023- MARZO 2024 | B4: SEGUNDO | C4: 2do | D4: A- | E4: PROGRAMACIÓN ORIENTADA A OBJETOS | F4: Desarrollar aplicaciones de mediana complejidad aplicando el entorno de programación orientado a objetos. La codificación de los conceptos de la programación orientada a objetos se la realizará en el lenguaje Java.
A5: ABRIL 2023 - AGOSTO 2024 | B5: TERCERO | C5: 3ro | D5: B+ | E5: PROGRAMACIÓN WEB, TRABAJO DE INTEGRACIÓN CURRICULAR | F5: Aplica conceptos, técnicas, herramientas de programación, que contribuyan con la implementación de soluciones de Software
A6: SEPTIEMBRE 2024- MARZO 2025 | B6: CUARTO | C6: 4to | D6: B- | E6: DESARROLLO WEB - BACK- END | F6: Diseña una servicio web consumible por un cliente web
A7: ABRIL - SEPTIEMBRE 2024 | B7: QUINTO | C7: 5to | D7: AB+ | E7: APLICACIONES MÓVILES HÍBRIDAS AVANZADA S | F7: Aplica los conceptos de la técnología móvil híbrida
A8: 2025-II | D8: AB-
D9: O+
D10: O-

Sheet DATOS
C1: IMPORTANTE: Antes de enviar a su tutor académico, favor actualizar las celdas marcadas con color rojo y verificar que toda la información esté correcta y sin faltas de ortografía en todo el documento.
A3: DATOS DE LA ENTIDAD RECEPTORA-DENOMINACIÓN COMERCIAL / DATOS ITV-CONVENIO
A4: DATOS DEL ESTUDIANTE
A6: Apellidos y Nombres Completos: | C6: ALVAREZ GONZALEZ JENIFER NATALIA
A7: Cédula: | C7: 1753746963
A8: Carrera: | C8: DESARROLLO DE SOFTWARE
A9: Nivel: | C9: QUINTO | D9: =IF(C9="PRIMERO","1ro",IF(C9="SEGUNDO","2do",IF(C9="TERCER","3ro",IF(C9="CUARTO","4to","5to")))) -> 5to
A10: E-mail: | C10: jng.alvarez@yavirac.edu.ec
A11: Teléfono: | C11: 0984828219
A12: Estado Civil | C12: SOLTERO | D12: Tipo de sangre: | E12: A+
A13: Domicilio | C13: Guamaní - Paquisha la Trinidad Oe5 y S58f | D13: Contacto de emergencia: | E13: América Gonzalez | F13: Telf. de emergencia: | H13: 0998954621
A14: DATOS DE LA CARRERA
A15: Coordinador de Carrera: | C15: MSc. Raúl Páez
A16: Docente Tutor | C16: Ing. Byron Moreno Moreno | E16: Cédula:
A19: Periodo Académico: | C19: 2025-II
A22: DATOS DEL PROYECTO EMPRESARIAL
A23: Nombre del Proyecto:
A24: SUPPORT IA, Documentación Marckdown MXP V2
A27: Cobertura y Localización: | C27: Región, Provincia, Ciudad, Parroquia
A28: Plazo de Ejecución: | C28: 5 AÑOS
A30: Fecha Inicio: | B30: =IF(D$9="1ro",A76,IF(D$9="2do",A76,IF(D$9="3ro",A76,IF(C$30="4to",B$76,IF(C$30="5to",B$76))))) -> 45992 | C30: =D$9 -> 5to | D30: 45810 | E30: 45870
A31: Fecha Final: | B31: =IF(D$9="1ro",A116,IF(D$9="2do",A116,IF(D$9="3ro",A116,IF(C$30="4to",B$111,IF(C$30="5to",B$111))))) -> 46045 | D31: 45817 | E31: Segundo Nivel
A32: INFORME FINAL | B32: =IF(C$30="1ro",A$116,IF(C$30="2do",A$116,IF(C$30="3ro",A$116,IF(C$30="4to",B$111,IF(C$30="5to",B$111))))) -> 46045
A35: DATOS DE LA EMPRESA BENEFICIARIA
A36: Razón Social: | C36: INT FOOD SERVICES CORP S.A
A37: Representante legal: | C37: GUARDERAS RIOFRIO ESTEBAN | E37: Cargo: | F37: REPRESENTANTE LEGAL
A38: Tutor empresarial: | C38: Ing. Carlos Zambrano
A39: Dirección: | C39: COREA número: 126 Intersección: AV.AMAZONAS Edificio: BELMONTE
A40: Teléfono: | C40: 0990517266
A41: E-mail: | C41: zetavx@gmail.com
A42: Provincia: | C42: Pichincha
A43: Cantón: | C43: Quito
A44: Parroquia: | C44: Iñaquito
A47: NO IMPRIMIR ESTE DOCUMENTO ES SOLAMENTE INFORMATIVO
A52: SOLTERO
A53: CASADO
A54: DIVORCIADO
A55: UNIÓN LIBRE
A56: Noviembre 2019 - Abril 2020
A57: Mayo 2020 - Octubre 2020
...

Sheet A. Carta Compromiso
B1: INSTITUTO SUPERIOR TECNOLÓGICO DE TURISMO Y PATRIMONIO YAVIRAC | F1: 010201
B2: MACROPROCESO 01 DOCENCIA
B3: PROCESO 02 PROCESO DE FORMACIÓN PRÁCTICA EN EL ENTORNO LABORAL REAL - FORMACIÓN DUAL
B4: FORMATO 01 CARTA DE PRESENTACIÓN Y ACTA COMPROMISO ESTUDIANTES
A6: D.M. Quito, | B6: =DATOS!B30 -> 45992
A8: Yo, | B8: =DATOS!C6 -> ALVAREZ GONZALEZ JENIFER NATALIA | C8: con C.C. | D8: =DATOS!C7 -> 1753746963 | E8: estudiante de | F8: =+DATOS!D9 -> 5to
A9: de la carrera | B9: =+DATOS!C8 -> DESARROLLO DE SOFTWARE | E9: en modalidad dual,
A10: DEL INSTITUTO SUPERIOR TECNOLÓGICO DE TURISMO Y PATRIMONIO YAVIRAC, | D10: asignado/a a
A11: =+DATOS!C36 -> INT FOOD SERVICES CORP S.A
A12: De acuerdo con el proyecto de carrera aprobado y vigente, en cumplimiento del currículo de la carrera, y en el marco del convenio firmado, me presento y, expreso mi interés y predisposición de realizar prácticas de formación dual, con el fin de cumplir con la planificación, ejecución, control y evaluación del proceso de desarrollo de las competencias laborales como estudiante de la carrera. Soy una persona que cumple con el perfil de ingreso de la carrera, y busco aprender y desarrollar los conocimientos, habilidades-destrezas y actitudes del perfil de egreso, y lograr las competencias como profesional de mi carrera. Por lo cual, solicito su aceptación para realizar mi proceso de formación práctica en el entorno laboral real en modalidad dual.
A13: A la vez que, me comprometo con acatar la normativa general vigente con las obligaciones establecidas en el Artículo 16 (Obligaciones generales del estudiante en modalidad dual) del Reglamento para Carreras y Programas en Modalidad de Formación Dual vigente, así como también, la normativa interna de la entidad formadora y, la normativa del Instituto. Reconociendo y aceptando entre otras prohibiciones expresas durante la Fase Práctica, las que se determinan a continuación: • Prohibición de consumo de alcohol. • Prohibición de consumo de sustancias estupefacientes, psicotrópicos y estimulantes. • Prohibición de tratos groseros e irrespetuosos a compañeros y del entorno (compañeros y demás personas involucradas) • Prohibición de desacatar las directrices de tutores empresariales y también de tutores académicos del instituto.
A14: También me comprometo en: * Garantizar la confidencialidad, reserva y protección de los datos e información proporcionados por la entidad receptora formadora, durante y después de mi fase práctica. * Y, promover un entorno social armónico, precautelar y salvaguardar la propiedad ajena y los bienes que pertenecen al sitio.
A15: Y así mismo, me comprometo en elaborar y presentar todos los documentos necesarios para validar el proceso de formación en modalidad dual, de acuerdo con lo establecido por la entidad receptora formadora y/o el Instituto, los cuáles deberán estar correctamente llenados y firmados.
A16: El incumplimiento a lo comprometido con la entidad receptora formadora y/o del Instituto, será causal para la toma de medidas disciplinarias conforme a las responsabilidades del proceso de formación en modalidad dual . De no dar cumplimiento con lo antes citado, puede conllevar bajo el debido proceso a la pérdida de la fase práctica.
A18: De manera libre y voluntaria acepto lo expresado y firmo como esta acta compromiso como constancia.
B21: Estudiante | C21: Firma
B23: =DATOS!C6 -> ALVAREZ GONZALEZ JENIFER NATALIA

Sheet C. Curriculum estandarizado
B1: INSTITUTO SUPERIOR TECNOLÓGICO DE TURISMO Y PATRIMONIO YAVIRAC | I1: 010202
B2: MACROPROCESO 01 DOCENCIA
B3: PROCESO 02 PROCESO DE FORMACIÓN PRÁCTICA EN EL ENTORNO LABORAL REAL - FORMACIÓN DUAL
B4: FORMATO 02 CURRÍCULO ESTANDARIZADO
A6: INSTITUTO SUPERIOR TECNOLÓGICO DE TURISMO Y PATRIMONIO "YAVIRAC"
A7: CÓDIGO: | C7: =DATOS!C7 -> 1753746963
A8: PERIODO ACADÉMICO: | C8: =DATOS!C19 -> 2025-II
A9: 1. DATOS PERSONALES
A10: Nombres y apellidos: | C10: =DATOS!C6 -> ALVAREZ GONZALEZ JENIFER NATALIA
A11: # identificación: | C11: =DATOS!C7 -> 1753746963
A12: Estado civil: | C12: =DATOS!C12 -> SOLTERO
A13: Teléfono: | C13: =DATOS!C11 -> 0984828219
A14: Domicilio: | C14: =DATOS!C13 -> Guamaní - Paquisha la Trinidad Oe5 y S58f
A16: Email institucional: | C16: =DATOS!C10 -> jng.alvarez@yavirac.edu.ec
A18: 2. DATOS ACADÉMICOS
A19: AÑO | B19: INSTITUCIÓN | F19: TITULO O MENCIÓN | H19: NOTA FINAL
A20: 2021 | B20: Unidad Educativa Comunitaria Intercultural Bilingue "Muyu Kawsay | F20: Bachiller en Ciencias | H20: 9.11
A21: 2023-En curso | B21: Instituto Superior Tecnológico de Turismo y Patrimonio "Yavirac" | F21: Tecnólogo en Desarrollo de Software | H21: En curso
A22: 3. EXPERIENCIA LABORAL
A23: AÑO | B23: INSTITUCIÓN O EMPRESA | F23: CARGO | H23: ACTIVIDADES DESARROLLADAS
A24: 2022 | B24: Bogati | F24: Polifuncional | H24: Manejo de caja e inventario, preparar productos
A25: 2025-actualidad | B25: INT FOOD SERVICES CORP S.A. | F25: Back-End y TICS | H25: Desarrollo y Entrenamiento de IAs
A26: 4. PRÁCTICAS DUALES
A27: AÑO | B27: INSTITUCIÓN O EMPRESA | F27: PUESTO DE APRENDIZAJE | H27: ACTIVIDADES DESARROLLADAS
A28: 2023-II | B28: INT FOOD SERVICES CORP S.A | F28: TICS | H28: Documentación Maxpoint Docusaurus
A29: 2024-I | B29: INT FOOD SERVICES CORP S.A | F29: Diseñador UX/UI | H29: Diseño de pantallas en Figma
A30: 2024-II | B30: INT FOOD SERVICES CORP S.A | F30: Back-End y TICS | H30: Desarrollo y Pruebas Unitarias API, con ASP.NET Core
A31: 2025-I | B31: INT FOOD SERVICES CORP S.A | F31: Back-End y TICS | H31: Desarrollo de API REST para manejo de errores con MongoDB
A33: 5. INFORMACIÓN ADICIONAL (LOGROS RELEVANTES, HABILIDADES, ETC.)
A34: AÑO | B34: INSTITUCIÓN | F34: LOGRO O HECHO RELEVANTE | H34: DETALLE DEL LOGRO O HECHO RELEVANTE
A35: 2023 | B35: freeCodeCamp | F35: JavaScript básico | H35: Un curso para adquirir principios esenciales de la programación en JavaScript. Dominar los principios esenciales de la programación en JavaScript. Dominar los principios esenciales de la programación en JavaScript. Dominar los principios esenciales de la programación en JavaScript. Dominar los principios esenciales de la programación en JavaScript. Dominar los principios esenciales de la programación en JavaScript. Dominar los principios esenciales de la programación en JavaScript. Dominar los principios esenciales de la programación en JavaScript. Dominar los principios esenciales de la programación en JavaScript.
A36: 2024 | B36: Certificación SCRUM Foundation | F36: Conocimiento básico Scrum | H36: Un reconocimiento básico sobre metodologías ágiles y gestión de proyectos con SCRUM
A37: 2024 | B37: La certificación Microsoft Azure Fundamentals (AZ-900) | F37: Conocimientos básicos Azure. | H37: Conocimientos básicos sobre la nube, sus servicios y modelos de implementación en Azure.
A38: 2025 | B38: Platzi | F38: Fundamentos basicos de IA. | H38: Curso práctico de fundamentos actuales de IA
B40: Atentamente,
B46: =DATOS!C6 -> ALVAREZ GONZALEZ JENIFER NATALIA
B47: NOMBRE Y FIRMA ESTUDIANTE

Sheet 1. PLAN MARCO
C1: INSTITUTO SUPERIOR TECNOLÓGICO DE TURISMO Y PATRIMONIO YAVIRAC | N1: DS-010203-4
C2: MACROPROCESO 01 DOCENCIA
C3: PROCESO 02 PROCESO DE FORMACIÓN PRÁCTICA EN EL ENTORNO LABORAL REAL - FORMACIÓN DUAL
C4: FORMATO 03 PLAN MARCO DE FORMACIÓN
A6: NOMBRE(S) DE ESTUDIANTE(S): | D6: =DATOS!C6 -> ALVAREZ GONZALEZ JENIFER NATALIA | I6: PERÍODO: | L6: 2025-II
A7: CARRERA: | D7: =DATOS!C8 -> DESARROLLO DE SOFTWARE | I7: NIVEL: | L7: =DATOS!C9 -> QUINTO
A8: EMPRESA FORMADORA: | D8: =DATOS!C36 -> INT FOOD SERVICES CORP S.A | I8: HORAS DE FORMACIÓN PRÁCTICA: | L8: 360
A9: DIRECCIÓN EMPRESA | D9: =DATOS!C39 -> COREA número: 126 Intersección: AV.AMAZONAS Edificio: BELMONTE | I9: NÚCLEO ESTRUCTURANTE: | L9: APLICACIONES MÓVILES HÍBRIDAS AVANZADAS
A10: NIVELES DE LOGRO ESPERADO
A11: 1: CONOCIMIENTOS BÁSICOS: El estudiante de la carrera dual debe familiarizarse con los contenidos y relaciones del área, de tal forma que pueda nombrarlos y diferenciarlos.
A12: 2: CONOCIMIENTOS: El estudiante de la carrera dual se debe formar en las competencias del área hasta el punto que las pueda aclarar y pueda dar información sobre las mismas.
A13: 3: PARTICIPACION EN LOS PROCEDIMIENTOS: El estudiante de la carrera dual debe adquirir las suficientes capacidades prácticas de tal forma que pueda realizar las tareas o pueda preparar su ejecución.
A14: 4: VALORACIÓN O ELABORACIÓN PROPIA DE PROCEDIMIENTOS DE TRABAJO: El estudiante de la carrera dual se debe formar en la aplicación práctica de tal forma que pueda realizar o elaborar las tareas sin indicaciones y además pueda evaluar una tarea de acuerdo a su criterio.
A16: OBJETIVOS DE LA FASE PRÁCTICA: Desarrollar aplicaciones utilizando nuevas tecnologías y en el estudiante aptitudes para planear e implementar pequeñas redes necesarias para la transmisión de datos.
A17: OBJETIVOS DE APRENDIZAJE: Al finalizar la fase práctica, el/la estudiante estará en capacidad de:
A18: No. | B18: Resultados de aprendizaje | E18: Nivel de Logro esperado | I18: Nivel real alcanzado | J18: Tareas laborales de aprendizaje a realizar para alcanzar el objetivo | L18: Puesto de aprendizaje (área o departamento de la empresa) | M18: No. de semanas de trabajo | N18: Responsable del puesto de aprendizaje
E19: (ponga una X en el número correspondiente)
E20: 1 | F20: 2 | G20: 3 | H20: 4 | I20: =AVERAGE(I21:I32) -> 3.0833333
A21: 1 | B21: Implementó sitio de 1 estática usando Docusaurus v3 con estructura modular y navegación autogenerada. | G21: X | I21: =IF(E21="X",1,IF(F21="X",2,IF(G21="X",3,IF(H21="X",4,0)))) -> 3 | J21: Instalar Docusaurus v3, configurar carpetas /docs y personalizar estilos CSS con branding corporativo. | L21: Desarrollo Back-End | M21: 8 | N21: Ing Byron Pérez
A22: 2 | B22: Diseñó instrucciones estructuradas para modelos de lenguaje orientados a tareas específicas. | G22: X | I22: =IF(E22="X",1,IF(F22="X",2,IF(G22="X",3,IF(H22="X",4,0)))) -> 3 | J22: Redactar prompts especializados definiendo roles, contexto y formato de salida en archivos Go.
A23: 3 | B23: Aplicó conceptos de RAG y embeddings vectoriales para sistemas de recuperación de información inteligente. | G23: X | I23: =IF(E23="X",1,IF(F23="X",2,IF(G23="X",3,IF(H23="X",4,0)))) -> 3 | J23: Integrar Gemini AI SDK, configurar MongoDB con índices vectoriales y desarrollar queries de búsqueda.
A24: 4 | B24: Diseñó sistema de agrupación y ordenamiento de fragmentos usando chunk_group families para presentación coherente. | G24: X | I24: =IF(E24="X",1,IF(F24="X",2,IF(G24="X",3,IF(H24="X",4,0)))) -> 3 | J24: Implementar lógica para agrupar chunks por familia, ordenar secuencialmente y reconstruir documentos.
A25: 5 | B25: Desarrolló estrategias de segmentación de texto considerando contexto y estructura semántica. | H25: X | I25: =IF(E25="X",1,IF(F25="X",2,IF(G25="X",3,IF(H25="X",4,0)))) -> 4 | J25: Configurar LangChain con RecursiveCharacterTextSplitter definiendo tamaños de chunk y overlap.
A26: 6 | B26: Desarrollo endpoints siguiendo clean architecture con validación. | G26: X | I26: =IF(E26="X",1,IF(F26="X",2,IF(G26="X",3,IF(H26="X",4,0)))) -> 3 | J26: Desarrollar handlers y services en Go con separación de capas y validación de errores. | L26: Desarrollo Back-End | N26: Ing Byron Pérez
A27: 7 | B27: Aplicó flujos de trabajo con ramas específicas para features, siguiendo estrategia de desarrollo colaborativo. | H27: X | I27: =IF(E27="X",1,IF(F27="X",2,IF(G27="X",3,IF(H27="X",4,0)))) -> 4 | J27: Crear branches feature, realizar commits, abrir pull requests y resolver conflictos de merge.
A28: 8 | B28: Creo prompts para generar casos de uso (Cockburn), modelos de BD y respuestas contextualizadas según rol de usuario. | G28: X | I28: =IF(E28="X",1,IF(F28="X",2,IF(G28="X",3,IF(H28="X",4,0)))) -> 3 | J28: Diseñar templates de prompts con variables dinámicas y ajustar según respuestas del modelo.
A29: 9 | B29: Elaboró documentación profesional aplicando estándares de presentación y organización de contenido. | G29: X | I29: =IF(E29="X",1,IF(F29="X",2,IF(G29="X",3,IF(H29="X",4,0)))) -> 3 | J29: Convertir documentos a Markdown, organizar en jerarquías y generar tabla de contenidos.
A30: 10 | B30: Implementó conteo preciso de tokens para chunking usando tiktoken en contextos de IA. | F30: X | I30: =IF(E30="X",1,IF(F30="X",2,IF(G30="X",3,IF(H30="X",4,0)))) -> 2 | J30: Importar tiktoken, implementar conteo de tokens antes de chunking y validar límites.
A31: 11 | B31: Diseñó sistemas de metadatos jerárquicos para clasificación de documentos técnicos. | G31: X | I31: =IF(E31="X",1,IF(F31="X",2,IF(G31="X",3,IF(H31="X",4,0)))) -> 3 | J31: Diseñar campos metadata y aplicar filtros de búsqueda por tipo de documento. | L31: Desarrollo Back-End | N31: Ing Byron Pérez
A32: 12 | B32: Aplicó diferentes técnicas de segmentación y chunking según tipo de documento y lenguaje. | G32: X | I32: =IF(E32="X",1,IF(F32="X",2,IF(G32="X",3,IF(H32="X",4,0)))) -> 3 | J32: Crear 7 chunkers especializados, configurar selección por context_type y validar con tests.
B33: Tutor Académico del ISTY | I33: Tutor Empresarial de la Empresa Formadora
B34: Nombre: | C34: Raúl Alejandro Paz Mundial | I34: Nombre: | J34: Mónica Patricia Bustán Gaona
B35: Firma: _________________________________________________ | I35: Firma:_________________________________________________

Sheet 2. PLAN DE ROTACION
C1: INSTITUTO SUPERIOR TECNOLÓGICO DE TURISMO Y PATRIMONIO YAVIRAC | L1: DS-010204-4
C2: MACROPROCESO 01 DOCENCIA
C3: PROCESO 02 PROCESO DE FORMACIÓN PRÁCTICA EN EL ENTORNO LABORAL REAL - FORMACIÓN DUAL
C4: FORMATO 04 PLAN DE APRENDIZAJE PRÁCTICO Y DE ROTACIÓN
A6: NOMBRE(S) DEL ESTUDIANTE(S): | C6: =DATOS!C6 -> ALVAREZ GONZALEZ JENIFER NATALIA
A7: CARRERA: | C7: =DATOS!C8 -> DESARROLLO DE SOFTWARE | D7: NIVEL: | E7: =DATOS!C9 -> QUINTO
A8: EMPRESA FORMADORA: | C8: =DATOS!C36 -> INT FOOD SERVICES CORP S.A | D8: HORAS DE FORMACIÓN PRÁCTICA: | E8: 360
A9: NÚCLEO ESTRUCTURANTE: | C9: APLICACIONES MÓVILES HÍBRIDAS AVANZADAS | D9: PERÍODO LECTIVO: | E9: 2025-II
A11: # | B11: Resultados de aprendizaje | D11: Puesto de aprendizaje (área o departamento de la empresa) | E11: DICIEMBRE | J11: ENERO
E12: S1 | F12: S2 | G12: S3 | H12: S4 | I12: S5 | J12: S6 | K12: S7 | L12: S8
E13: 1 - 4 | F13: 45999 | G13: 15-19 | H13: 22-26 | I13: 29-31 | J13: 5- 9 | K13: 12-16 | L13: 19-23
A14: 1 | B14: Implementó sitio de 1 estática usando Docusaurus v3 con estructura modular y navegación autogenerada. | D14: Desarrollo | E14: X | L14: Defensa de Proyecto empresarial
A15: 2 | B15: Diseñó instrucciones estructuradas para modelos de lenguaje orientados a tareas específicas. | F15: X
A16: 3 | B16: Aplicó conceptos de RAG y embeddings vectoriales para sistemas de recuperación de información inteligente. | G16: X
A17: 4 | B17: Diseñó sistema de agrupación y ordenamiento de fragmentos usando chunk_group families para presentación coherente. | H17: X
A18: 5 | B18: Desarrolló estrategias de segmentación de texto considerando contexto y estructura semántica. | I18: X
A19: 6 | B19: Desarrollo endpoints siguiendo clean architecture con validación. | D19: Desarrollo | J19: X
A20: 7 | B20: Aplicó flujos de trabajo con ramas específicas para features, siguiendo estrategia de desarrollo colaborativo. | H20: X | J20: X
A21: 8 | B21: Creo prompts para generar casos de uso (Cockburn), modelos de BD y respuestas contextualizadas según rol de usuario. | J21: X
A22: 9 | B22: Elaboró documentación profesional aplicando estándares de presentación y organización de contenido. | J22: X
A23: 10 | B23: Implementó conteo preciso de tokens para chunking usando tiktoken en contextos de IA. | J23: X
A24: 11 | B24: Diseñó sistemas de metadatos jerárquicos para clasificación de documentos técnicos. | D24: Desarrollo | J24: X | K24: X
A25: 12 | B25: Aplicó diferentes técnicas de segmentación y chunking según tipo de documento y lenguaje. | L25: X
A26: COMPETENCIAS NECESARIAS
A27: CONOCIMIENTOS TEÓRICOS | D27: PROCEDIMENTALES | H27: ACTITUDINALES
A28: Desarrollo de aplicaciones aplicando arquitectura cliente - servidor | D28: Manejo de procesos, lenguajes de programación y frameworks | H28: Proactividad, creatividad, analítico
B33: Tutor Académico del ISTY | D33: Tutor Empresarial de la Empresa Formadora
B34: Nombre: | C34: Raúl Alejandro Paz Mundial | D34: Nombre: | E34: Mónica Patricia Bustán Gaona
B35: Firma: _________________________________________________ | D35: Firma:_________________________________________________

Sheet 3. Registro de Asistencia
C1: INSTITUTO SUPERIOR TECNOLÓGICO DE TURISMO Y PATRIMONIO YAVIRAC | J1: 010205
C2: MACROPROCESO 01 DOCENCIA
C3: PROCESO 02 PROCESO DE FORMACIÓN PRÁCTICA EN EL ENTORNO LABORAL REAL - FORMACIÓN DUAL
C4: FORMATO 05 ACTA DE ASISTENCIA
A6: EMPRESA FORMADORA: | C6: =DATOS!C36 -> INT FOOD SERVICES CORP S.A | G6: CARRERA: | H6: =DATOS!C8 -> DESARROLLO DE SOFTWARE
A7: TUTOR(A) ACADÉMICO: | C7: =DATOS!C16 -> Ing. Byron Moreno Moreno | G7: PERÍODO ACADÉMICO: | H7: =DATOS!C19 -> 2025-II
A8: TUTOR(A) EMPRESARIAL: | C8: =DATOS!C38 -> Ing. Carlos Zambrano | G8: NIVEL: | H8: =DATOS!C9 -> QUINTO
A9: NOMBRE DEL ESTUDIANTE: | C9: =DATOS!C6 -> ALVAREZ GONZALEZ JENIFER NATALIA | G9: NÚCLEO ESTRUCTURANTE: | H9: =+IF(H8="PRIMERO",DATOS!O69,IF(H8="SEGUNDO",DATOS!O70,IF(H8="TERCERO",DATOS!O71,IF(H8="CUARTO",DATOS!O72,DATOS!O73)))) -> APLICACIONES MÓVILES HÍBRIDAS AVANZADAS
A10: E-MAIL INSTITUCIONAL: | C10: =DATOS!C10 -> jng.alvarez@yavirac.edu.ec | G10: TELÉFONO DE EMERGENCIA: | H10: =DATOS!H13 -> 0998954621
A11: TELÉFONO / MÓVIL: | C11: =DATOS!C11 -> 0984828219 | G11: CONTACTO DE EMERGENCIA: | H11: =DATOS!E13 -> América Gonzalez
A12: CÉDULA: | C12: =DATOS!C7 -> 1753746963 | G12: TIPO DE SANGRE: | H12: =DATOS!E12 -> A+
A14: N° | B14: Fecha | C14: Hora Ingreso | D14: Almuerzo | E14: Hora Salida | F14: Horas al día | G14: Firma estudiante | H14: Observaciones:
A15: 1 | B15: 45992 | C15: 09H00 | D15: 12H30 - 13H30 | E15: 18H00 | F15: 8 | H15: S/N
A16: 2 | B16: 45993 | C16: 09H00 | D16: 12H30 - 13H30 | E16: 18H00 | F16: 8 | H16: S/N
A17: 3 | B17: 45994 | C17: 09H00 | D17: 12H30 - 13H30 | E17: 18H00 | F17: 8 | H17: S/N
A18: 4 | B18: 45995 | C18: 09H00 | D18: 12H30 - 13H30 | E18: 18H00 | F18: 8 | H18: S/N
A19: 5 | B19: 45999 | C19: 09H00 | D19: 12H30 - 13H30 | E19: 18H00 | F19: 8 | H19: S/N
A20: 6 | B20: 46000 | C20: 09H00 | D20: 12H30 - 13H30 | E20: 18H00 | F20: 8 | H20: S/N
A21: 7 | B21: 46001 | C21: 09H00 | D21: 12H30 - 13H30 | E21: 18H00 | F21: 8 | H21: S/N
A22: 8 | B22: 46002 | C22: 09H00 | D22: 12H30 - 13H30 | E22: 18H00 | F22: 8 | H22: S/N
A23: 9 | B23: 46003 | C23: 09H00 | D23: 12H30 - 13H30 | E23: 18H00 | F23: 8 | H23: S/N
A24: 10 | B24: 46006 | C24: 09H00 | D24: 12H30 - 13H30 | E24: 18H00 | F24: 8 | H24: S/N
A25: 11 | B25: 46007 | C25: 09H00 | D25: 12H30 - 13H30 | E25: 18H00 | F25: 8 | H25: S/N
A26: 12 | B26: 46008 | C26: 09H00 | D26: 12H30 - 13H30 | E26: 18H00 | F26: 8 | H26: S/N
... A50: 36 | B50: 46045 | C50: 09H00 | D50: 12H30 - 13H30 | E50: 18H00 | F50: 8 | H50: S/N
A51: 37 | B51: 01/12/2025 - 23/01/2026 | C51: - | D51: - | E51: - | F51: 72 | H51: HORAS AUTÓNOMAS
C52: TOTAL HORAS FASE PRÁCTICA: | F52: =SUM(F15:F51) -> 360

Sheet 4. Informe de Aprendizaje
C1: INSTITUTO SUPERIOR TECNOLÓGICO DE TURISMO Y PATRIMONIO YAVIRAC | AA1: DS-010206
C2: MACROPROCESO 01 DOCENCIA
C3: PROCESO 02 PROCESO DE FORMACIÓN PRÁCTICA EN EL ENTORNO LABORAL REAL - FORMACIÓN DUAL
C4: FORMATO 06 BITÁCORA DE APRENDIZAJE DE FASE PRÁCTICA
A6: EMPRESA FORMADORA: | D6: =DATOS!C36 -> INT FOOD SERVICES CORP S.A | N6: NIVEL: | S6: =DATOS!C9 -> QUINTO
A7: ESTUDIANTE: | D7: =DATOS!C6 -> ALVAREZ GONZALEZ JENIFER NATALIA | N7: CICLO ACADÉMICO: | S7: =DATOS!C19 -> 2025-II
A8: CÉDULA: | D8: =DATOS!C7 -> 1753746963 | N8: F. INICIO FASE PRÁCTICA | S8: =DATOS!B30 -> 45992 | X8: F. FIN FASE PRÁCTICA | Z8: =DATOS!B31 -> 46045
A9: TUTOR(A) ACADÉMICO | D9: =DATOS!C16 -> Ing. Byron Moreno Moreno | N9: NÚCLEO ESTRUCTURANTE: | S9: =+IF(S6="PRIMERO",DATOS!O69,IF(S6="SEGUNDO",DATOS!O70,IF(S6="TERCERO",DATOS!O71,IF(S6="CUARTO",DATOS!O72,DATOS!O73)))) -> APLICACIONES MÓVILES HÍBRIDAS AVANZADAS
A10: TUTOR(A) EMPRESARIAL | D10: =DATOS!C38 -> Ing. Carlos Zambrano | N10: CARRERA | S10: =DATOS!C8 -> DESARROLLO DE SOFTWARE
A12: OBJETIVO DEL NÚCLEO ESTRUCTURANTE PARA LA FASE PRÁCTICA
A13: =IF(S6="PRIMERO",DATOS!T69,IF(S6="SEGUNDO",DATOS!T70,IF(S6="TERCERO",DATOS!T71,IF(S6="CUARTO",DATOS!T72,DATOS!T73)))) -> Aplica los conceptos de la técnología móvil híbrida
A15: INFORME DE APRENDIZAJE DE LA FASE PRÁCTICA
A16: SEMANA | B16: FECHA | D16: PUESTO DE APRENDIZAJE | H16: ACTIVIDADES REALIZADAS | T16: ACTIVIDADES AUTÓNOMAS
A17: 1 | B17: 01/12/2025 - 04/12/2025 | D17: Back-End | H17: Instalar y configurar Docusaurus v3, crear estructura de carpetas y aplicar estilos CSS corporativos | T17: Leer documentación oficial de Docusaurus y practicar configuración básica.
A18: 2 | B18: 08/12/2025 - 12/12/2025 | D18: Back-End | H18: Convertir documentación técnica a Markdown, organizar jerarquías y generar navegación automática. | T18: Investigar sintaxis Markdown y convertir documentos de ejemplo.
A19: 3 | B19: 15/12/2025 - 19/12/2025 | D19: Back-End | H19: Integrar Gemini AI SDK, configurar MongoDB Atlas con índices vectoriales y desarrollar queries. | T19: Estudiar conceptos de embeddings vectoriales y MongoDB Atlas.
A20: 4 | B20: 22/12/2025 - 26/12/2025 | D20: Back-End | H20: Redactar prompts especializados por rol, diseñar templates con variables dinámicas y validar respuestas. | T20: Investigar técnicas de prompt engineering y probar ejemplos.
A21: 5 | B21: 29/12/2025 - 31/12/2025 | D21: Back-End | H21: Implementar conteo de tokens con tiktoken, configurar LangChain y definir estrategias de chunking. | T21: Leer documentación de LangChain y tiktoken para chunking.
A22: 6 | B22: 05/01/2026 - 09/01/2026 | D22: Back-End | H22: Crear 7 chunkers especializados por tipo de documento, implementar selección automática por context_type. | T22: Analizar estrategias de segmentación según tipo de contenido.
A23: 7 | B23: 12/01/2026 - 16/01/2026 | D23: Back-End | H23: Desarrollar lógica de agrupación por familias, reconstrucción de chunks y diseño de metadatos jerárquicos. | T23: Estudiar patrones de metadatos y reconstrucción de documentos.
A24: 8 | B24: 19/01/2026 - 23/01/2026 | D24: Back-End | H24: Desarrollar endpoints REST en Go con clean architecture, crear branches Git y validar con tests unitarios. | T24: Revisar principios de clean architecture y testing unitario.
A25: Reflexión sobre el aprendizaje alcanzado de las actividades realizadas en la empresa formadora | D25: Durante las prácticas desarrollé habilidades en inteligencia artificial implementando un sistema RAG modular. Aprendí arquitectura hexagonal, embeddings vectoriales, chunking estratégico e integración con Gemini AI. La experiencia con Git y documentación técnica fortaleció mi capacidad para trabajo colaborativo en desarrollo de software. | Q25: Observaciones de la empresa formadora sobre el desempeño del estudiante: | T25: NINGUNA

Sheet 5. Evaluacion-Empresarial (NUEV
F1: INSTITUTO SUPERIOR TECNOLÓGICO DE TURISMO Y PATRIMONIO YAVIRAC | Y1: DS-010207
F2: MACROPROCESO 01 DOCENCIA
F3: PROCESO 02 PROCESO DE FORMACIÓN PRÁCTICA EN EL ENTORNO LABORAL REAL - FORMACIÓN DUAL
F4: FORMATO 07 INFORME DE EVALUACIÓN POR PARTE DE LA ENTIDAD FORMADORA
A6: EMPRESA FORMADORA: | F6: =DATOS!C36 -> INT FOOD SERVICES CORP S.A | N6: NIVEL: | R6: =DATOS!C9 -> QUINTO
A7: ESTUDIANTE: | F7: =DATOS!C6 -> ALVAREZ GONZALEZ JENIFER NATALIA | N7: CICLO ACADÉMICO: | R7: =DATOS!C19 -> 2025-II
A8: CÉDULA: | F8: =DATOS!C7 -> 1753746963 | N8: F. INICIO FASE PRÁCTICA | R8: =DATOS!B30 -> 45992 | V8: F. FIN FASE PRÁCTICA | X8: =DATOS!B31 -> 46045
A9: TUTOR(A) ACADÉMICO | F9: =DATOS!C16 -> Ing. Byron Moreno Moreno | N9: N. ESTRUCTURANTE: | R9: =IF(R6="PRIMERO",DATOS!O69,IF(R6="SEGUNDO",DATOS!O70,IF(R6="TERCERO",DATOS!O71,IF(R6="CUARTO",DATOS!O72,DATOS!O73)))) -> APLICACIONES MÓVILES HÍBRIDAS AVANZADAS
A10: TUTOR(A) EMPRESARIAL | F10: =DATOS!C38 -> Ing. Carlos Zambrano | N10: CARRERA | R10: =DATOS!C8 -> DESARROLLO DE SOFTWARE
A12: OBJETIVO DEL NÚCLEO ESTRUCTURANTE PARA LA FASE PRÁCTICA
A13: =IF(R6="PRIMERO",DATOS!T69,IF(R6="SEGUNDO",DATOS!T70,IF(R6="TERCERO",DATOS!T71,IF(R6="CUARTO",DATOS!T72,DATOS!T73)))) -> Aplica los conceptos de la técnología móvil híbrida
B15: EVALUACIÓN DE DESEMPEÑO | I15: NOTA (10 PUNTOS) | L15: DEFENSA PROYECTO TUTOR EMPRESARIAL | P15: Excelente | Q15: Bueno | R15: Regular | S15: Deficiente | T15: NOTA PARCIAL
B16: Logro de Objetivos de Aprendizaje | I16: 8
B17: Desempeño en los puestos de trabajo y actividades asignadas (Plan de rotación) | I17: 7 | L17: CRITERIOS | P17: 4 | Q17: 3 | R17: 2 | S17: 1
B18: Capacidad de aplicar los conocimientos en la práctica. | I18: 8 | L18: Presentación en tiempo y forma (formato, normas APA, cronograma) | Q18: 3 | T18: 3
B19: Capacidad de comunicación oral y escrita. | I19: 9 | L19: Calidad de la presentación (uso ayudas técnicas y audiovisuales,etc.) | P19: 4 | T19: 4
B20: Capacidad de investigación, aprender y actualizarse permanentemente | I20: 9 | L20: Dominio del contenido | P20: 4 | T20: 4
B21: Capacidad creativa. | I21: 8 | L21: Claridad y precisión en la exposición | Q21: 3 | T21: 3
B22: Capacidad para identificar, plantear y resolver problemas. | I22: 9 | L22: Satisfacción de la Empresa Formadora | P22: 4 | T22: 4
B23: Capacidad de trabajo en equipo y capacidades interpersonales | I23: 8 | L23: Nota Parcial de la Defensa del Proyecto: | T23: =SUM(T18:T22) -> 18
B24: Valoración y respecto por la diversidad y multiculturalidad. | I24: 8 | L24: Nota Final de la Defensa del Proyecto: | T24: =T23*10/20 -> 9
B25: Habilidad para trabajar en forma autónoma. | I25: 10 | L25: Nota ponderada sobre 3 puntos: | T25: =T24*0.3 -> 2.7
B28: PROMEDIO | I28: =AVERAGE(I16:I27) -> 8.4 | L28: NOTA FINAL EMPRESA | P28: =I29+T25 -> 8.58
B29: Nota ponderada sobre 7 puntos | I29: =I28*0.7 -> 5.88
B32: COMENTARIOS / OBSERVACIONES:

Sheet 6. Evaluación Instituto (NUEVO)
F2: INSTITUTO SUPERIOR TECNOLÓGICO DE TURISMO Y PATRIMONIO YAVIRAC | AB2: DS -010208
F3: MACROPROCESO 01 DOCENCIA
F4: PROCESO 02 PROCESO DE FORMACIÓN PRÁCTICA EN EL ENTORNO LABORAL REAL - FORMACIÓN DUAL
F5: FORMATO 08 INFORME DE EVALUACIÓN POR PARTE DEL INSTITUTO
A7: EMPRESA FORMADORA: | F7: =DATOS!C36 -> INT FOOD SERVICES CORP S.A | R7: NIVEL: | W7: =DATOS!C9 -> QUINTO
A8: ESTUDIANTE: | F8: =DATOS!C6 -> ALVAREZ GONZALEZ JENIFER NATALIA | R8: CICLO ACADÉMICO: | W8: =DATOS!C19 -> 2025-II
A9: CÉDULA: | F9: =DATOS!C7 -> 1753746963 | R9: F. INICIO FASE PRÁCTICA | W9: =DATOS!B30 -> 45992 | Y9: F. FIN FASE PRÁCTICA | AA9: =DATOS!B31 -> 46045
A10: TUTOR(A) ACADÉMICO | F10: =DATOS!C16 -> Ing. Byron Moreno Moreno | R10: N. ESTRUCTURANTE: | W10: =+IF(W7="PRIMERO",DATOS!O69,IF(W7="SEGUNDO",DATOS!O70,IF(W7="TERCERO",DATOS!O71,IF(W7="CUARTO",DATOS!O72,DATOS!O73)))) -> APLICACIONES MÓVILES HÍBRIDAS AVANZADAS
A11: TUTOR(A) EMPRESARIAL | F11: =DATOS!C38 -> Ing. Carlos Zambrano | R11: CARRERA | W11: =DATOS!C8 -> DESARROLLO DE SOFTWARE
A13: OBJETIVO DEL NÚCLEO ESTRUCTURANTE PARA LA FASE PRÁCTICA
A14: =IF(W7="PRIMERO",DATOS!T69,IF(W7="SEGUNDO",DATOS!T70,IF(W7="TERCERO",DATOS!T71,IF(W7="CUARTO",DATOS!T72,DATOS!T73)))) -> Aplica los conceptos de la técnología móvil híbrida
A16: DEFENSA PROYECTO TUTOR ACADÉMICO | E16: Excelente | F16: Bueno | G16: Regular | H16: Deficiente | I16: NOTA PARCIAL | K16: TEMA | Q16: PARÁMETROS PROYECTO EMPRESARIAL | AA16: NOTA
A17: CRITERIOS | E17: 4 | F17: 3 | G17: 2 | H17: 1 | K17: =DATOS!A24 -> SUPPORT IA, Documentación Marckdown MXP V2 | Q17: 1.Proactividad, independencia y compromiso demostrado en la elaboración del proyecto | AA17: 9
A18: Presentación en tiempo y forma (formato, normas APA, cronograma) | F18: 3 | I18: =SUM(E18:H18) -> 3 | Q18: 2. Plazo y calidad en la entrega de documentos | AA18: 9
A19: Calidad de la presentación (uso ayudas técnicas y audiovisuales,etc.) | F19: 3 | I19: =SUM(E19:H19) -> 3 | Q19: 3. Cumplimiento de parametros en el proyecto empresarial escrito | AA19: 9
A20: Dominio del contenido | E20: 4 | I20: =SUM(E20:H20) -> 4 | Q20: 4. Desarrollo del proyecto en profundidad y aporte a la solución del problema | AA20: 9
A21: Claridad y precisión en la exposición | E21: 4 | I21: =SUM(E21:H21) -> 4 | Q21: 5. Cumplimiento de requerimientos / objetivos planteados al inicio del proyecto | AA21: 9
A22: Satisfacción de la Empresa Formadora | F22: 3 | I22: =SUM(E22:H22) -> 3 | Q22: 6. Uso de metodología científica y aplicación de normas bibliográficas | AA22: 9
A23: Nota Parcial de la Defensa del Proyecto: | I23: =SUM(I18:I22) -> 17 | Q23: 7. Aporte al proyecto acorde al nivel académico | AA23: 9
A24: Nota Final de la Defensa del Proyecto: | I24: =I23*10/20 -> 8.5 | Q24: Promedio Parcial del Proyecto Empresarial: | AA24: =AVERAGE(AA17:AA23) -> 9
A25: Nota ponderada sobre 3 puntos | I25: =I24*0.3 -> 2.55 | Q25: Nota ponderada sobre 7 puntos | AA25: =AA24*0.7 -> 6.3
A27: EVALUACIÓN FINAL CONSOLIDADO EMPRESA - INSTITUTO | P27: COMENTARIOS / OBSERVACIONES:
A28: EVALUACIÓN EMPRESA | H28: EVALUACIÓN INSTITUTO
A29: ='5. Evaluacion-Empresarial (NUEV'!P28 -> 8.58 | H29: =I25+AA25 -> 8.85
A31: PROMEDIO FINAL FASE PRÁCTICA: | H31: =(+A29*0.5)+(H29*0.5) -> 8.715

Sheet Hoja de Ruta
A10: REGISTRO DE VISITAS INSTITUCIONALES O EMPRESARIALES/TUTORÍAS FASES PRÁCTICAS
A11: HOJA DE RUTA
A13: NOMBRE DEL DOCENTE:
A14: N° | B14: Intitución/Empresa a la que se visita | C14: Asunto | D14: Contacto | E14: Teléfono | F14: Firma Institución/Empresa | G14: Fecha | H14: Hora Salida del ISTY | I14: Hora llegada a reunión | J14: Hora Finalización de Reunión | K14: OBSERVACIONES
A15: 1
A16: 2
A17: 3
A18: 4
A19: 5
A20: 6
A21: 7
A22: 8
A23: 9
A24: 10

Sheet SOLICITUD ALUMNO
A10: INSTITUTO SUPERIOR TECNOLÓGICO DE TURISMO Y PATRIMONIO "YAVIRAC"
A11: Dirección: García Moreno S-435 y Ambato
A12: Quito - Ecuador
E14: Quito DM., | F14: =TODAY() -> 46127
A16: Magíster
A17: Gabriela Coral
A18: COORDINADORA DE VINCULACIÓN DEL IST YAVIRAC
A19: Presente.-
A21: De mis consideraciones:
A23: Después de expresarle un caluroso saludo y éxitos en sus funciones, me permito remitirle la siguiente Solicitud:
A25: Yo, | B25: =DATOS!C6 -> ALVAREZ GONZALEZ JENIFER NATALIA | E25: con C.C. Nro. | F25: =DATOS!C7 -> 1753746963 | G25: estudiante de la carrera de
A26: =DATOS!C8 -> DESARROLLO DE SOFTWARE | D26: me dirijo a Ud., para solicitarle de la manera más comedida se confiera
A27: un certificado de haber realizado el Servicio a la Comunidad y las Prácticas pre profesionales, mismo que es
A28: necesario presentarlo como requisito para la defensa del Proyecto de Titulación contemplado en la Coordinación
A29: de Titulación del Instituto Superior Tecnológico de Turismo y Patrimonio Yavirac.
A31: Por la favorable atención que se digne dar al presente, le anticipo mis sentidos agradecimientos.
A34: Atentamente,
A35: FIRMA COLOR AZUL (ESTE DOCUMENTO SE DEBE ENVIAR SOLAMENTE SI YA CUMPLIÓ CON PRÁCTICAS Y VINCULACIÓN)
A41: =DATOS!C6 -> ALVAREZ GONZALEZ JENIFER NATALIA
A42: =DATOS!C7 -> 1753746963
A43: =DATOS!C10 -> jng.alvarez@yavirac.edu.ec
A44: =DATOS!C11 -> 0984828219
